Workbook

Sheet FSS & VESDA
A1: Daily FSS & VESDA System Check
A2: Date | B2: Location Name | C2: Gas Release panel (auto/manual) | D2: Detectors LED Blinking (yes/No | E2: Inergen Pressure in green band (Yes/No) | F2: Smoke Detector Visible (Yes/No) | G2: FM nozle area clean (Yes/No) | H2: Any alarm on FAS (Yes/No) | I2: VESDA pipe (Ok/Not ok) | J2: Any loose Connection of batttery terminals (Yes/No) | K2: Panel Battery Voltage (V) | L2: Technician | M2: Remarks
A3: 46082 | B3: Swith Room | C3: Auto | D3: Yes | E3: No | F3: Yes | G3: Yes | H3: No | I3: Ok | J3: No | K3: 24 | L3: CHOMBA | M3: OK
B4: IBM Room | C4: Auto | D4: Yes | E4: Yes | F4: Yes | G4: Yes | H4: No | I4: Ok | J4: No | K4: 24
B5: Power Room | C5: Auto | D5: Yes | E5: Yes | F5: Yes | G5: Yes | H5: No | I5: Ok | J5: No | K5: 24
B6: Battery Room | C6: Auto | D6: Yes | E6: Yes | F6: Yes | G6: Yes | H6: No | I6: Ok | J6: No | K6: 24
B7: Enterprise Room 1 | C7: Auto | D7: Yes | E7: Yes | F7: Yes | G7: Yes | H7: No | I7: Ok | J7: No | K7: 24
B8: Enterprise Room 2 | C8: Auto | D8: Yes | E8: Yes | F8: Yes | G8: Yes | H8: No | I8: Ok | J8: No | K8: 24
A9: 46083 | B9: Swith Room | C9: Auto | D9: Yes | E9: No | F9: Yes | G9: Yes | H9: No | I9: Ok | J9: No | K9: 24 | L9: CHOMBA | M9: OK
B10: IBM Room | C10: Auto | D10: Yes | E10: Yes | F10: Yes | G10: Yes | H10: No | I10: Ok | J10: No | K10: 24
B11: Power Room | C11: Auto | D11: Yes | E11: Yes | F11: Yes | G11: Yes | H11: No | I11: Ok | J11: No | K11: 24
B12: Battery Room | C12: Auto | D12: Yes | E12: Yes | F12: Yes | G12: Yes | H12: No | I12: Ok | J12: No | K12: 24
B13: Enterprise Room 1 | C13: Auto | D13: Yes | E13: Yes | F13: Yes | G13: Yes | H13: No | I13: Ok | J13: No | K13: 24
B14: Enterprise Room 2 | C14: Auto | D14: Yes | E14: Yes | F14: Yes | G14: Yes | H14: No | I14: Ok | J14: No | K14: 24
A15: 46084 | B15: Swith Room | C15: Auto | D15: Yes | E15: No | F15: Yes | G15: Yes | H15: No | I15: Ok | J15: No | K15: 24 | L15: CHOMBA | M15: OK
B16: IBM Room | C16: Auto | D16: Yes | E16: Yes | F16: Yes | G16: Yes | H16: No | I16: Ok | J16: No | K16: 24
B17: Power Room | C17: Auto | D17: Yes | E17: Yes | F17: Yes | G17: Yes | H17: No | I17: Ok | J17: No | K17: 24
B18: Battery Room | C18: Auto | D18: Yes | E18: Yes | F18: Yes | G18: Yes | H18: No | I18: Ok | J18: No | K18: 24
B19: Enterprise Room 1 | C19: Auto | D19: Yes | E19: Yes | F19: Yes | G19: Yes | H19: No | I19: Ok | J19: No | K19: 24
B20: Enterprise Room 2 | C20: Auto | D20: Yes | E20: Yes | F20: Yes | G20: Yes | H20: No | I20: Ok | J20: No | K20: 24
A21: 46085 | B21: Swith Room | C21: Auto | D21: Yes | E21: No | F21: Yes | G21: Yes | H21: No | I21: Ok | J21: No | K21: 24 | L21: CHOMBA | M21: OK
B22: IBM Room | C22: Auto | D22: Yes | E22: Yes | F22: Yes | G22: Yes | H22: No | I22: Ok | J22: No | K22: 24
B23: Power Room | C23: Auto | D23: Yes | E23: Yes | F23: Yes | G23: Yes | H23: No | I23: Ok | J23: No | K23: 24
B24: Battery Room | C24: Auto | D24: Yes | E24: Yes | F24: Yes | G24: Yes | H24: No | I24: Ok | J24: No | K24: 24
B25: Enterprise Room 1 | C25: Auto | D25: Yes | E25: Yes | F25: Yes | G25: Yes | H25: No | I25: Ok | J25: No | K25: 24
B26: Enterprise Room 2 | C26: Auto | D26: Yes | E26: Yes | F26: Yes | G26: Yes | H26: No | I26: Ok | J26: No | K26: 24
A27: 46086 | B27: Swith Room | C27: Auto | D27: Yes | E27: No | F27: Yes | G27: Yes | H27: No | I27: Ok | J27: No | K27: 24 | L27: CHOMBA | M27: OK
B28: IBM Room | C28: Auto | D28: Yes | E28: Yes | F28: Yes | G28: Yes | H28: No | I28: Ok | J28: No | K28: 24
B29: Power Room | C29: Auto | D29: Yes | E29: Yes | F29: Yes | G29: Yes | H29: No | I29: Ok | J29: No | K29: 24
B30: Battery Room | C30: Auto | D30: Yes | E30: Yes | F30: Yes | G30: Yes | H30: No | I30: Ok | J30: No | K30: 24
B31: Enterprise Room 1 | C31: Auto | D31: Yes | E31: Yes | F31: Yes | G31: Yes | H31: No | I31: Ok | J31: No | K31: 24
B32: Enterprise Room 2 | C32: Auto | D32: Yes | E32: Yes | F32: Yes | G32: Yes | H32: No | I32: Ok | J32: No | K32: 24
A33: 46087 | B33: Swith Room | C33: Auto | D33: Yes | E33: No | F33: Yes | G33: Yes | H33: No | I33: Ok | J33: No | K33: 24 | L33: CHOMBA | M33: OK
B34: IBM Room | C34: Auto | D34: Yes | E34: Yes | F34: Yes | G34: Yes | H34: No | I34: Ok | J34: No | K34: 24
B35: Power Room | C35: Auto | D35: Yes | E35: Yes | F35: Yes | G35: Yes | H35: No | I35: Ok | J35: No | K35: 24
B36: Battery Room | C36: Auto | D36: Yes | E36: Yes | F36: Yes | G36: Yes | H36: No | I36: Ok | J36: No | K36: 24
B37: Enterprise Room 1 | C37: Auto | D37: Yes | E37: Yes | F37: Yes | G37: Yes | H37: No | I37: Ok | J37: No | K37: 24
B38: Enterprise Room 2 | C38: Auto | D38: Yes | E38: Yes | F38: Yes | G38: Yes | H38: No | I38: Ok | J38: No | K38: 24
A39: 46088 | B39: Swith Room | C39: Auto | D39: Yes | E39: No | F39: Yes | G39: Yes | H39: No | I39: Ok | J39: No | K39: 24 | L39: PETER | M39: OK
B40: IBM Room | C40: Auto | D40: Yes | E40: Yes | F40: Yes | G40: Yes | H40: No | I40: Ok | J40: No | K40: 24
...

Sheet Inergen Gas Cylinder
A1: Daily Inergen Gas Cylinder Check (Pressure Gauge)
A2: Date | B2: Time | C2: Cyl-1 | D2: Cyl-2 | E2: Cyl-3 | F2: Cyl-4 | G2: Cyl-5 | H2: Cyl-6 | I2: Cyl-7 | J2: Cyl-8 | K2: Cyl-9 | L2: Cyl-10 | M2: Cyl-11 | N2: Cyl-12 | O2: Cyl-13 | P2: Cyl-14 | Q2: Cyl-15 | R2: Cyl-16 | S2: Cyl-17 | T2: Cyl-18 | U2: Cyl-19 | V2: Cyl-20 | W2: Cyl-21 | X2: Cyl-22 | Y2: Cyl-23 | Z2: Cyl-24 | AA2: Cyl-25 | AB2: Cyl-26 | AC2: Cyl-27 | AD2: Cyl-28 | AE2: Cyl-29 | AF2: Cyl-30 | AG2: Cyl-31 | AH2: Cyl-32 | AI2: Cyl-33 | AJ2: Cyl-34 | AK2: Cyl-35 | AL2: Cyl-36 | AM2: Cyl-37 | AN2: Cyl-38 | AO2: Cyl-39 | AP2: Cyl-40 | AQ2: Cyl-41 | AR2: Cyl-42 | AS2: Cyl-43 | AT2: Cyl-44 | AU2: Cyl-45 | AV2: Cyl-46 | AW2: Cyl-47 | AX2: Cyl-48 | AY2: Cyl-49 | AZ2: Cyl-50 | BA2: Cyl-51 | BB2: Cyl-52 | BC2: Cyl-53 | BD2: Cyl-54 | BE2: Cyl-55 | BF2: Cyl-56 | BG2: Cyl-57 | BH2: Cyl-58 | BI2: Cyl-59 | BJ2: Cyl-60 | BK2: Cyl-61 | BL2: Cyl-62 | BM2: Cyl-63 | BN2: Cyl-64 | BO2: Cyl-65 | BP2: Cyl-66 | BQ2: Cyl-67 | BR2: Technician Name | BS2: Remarks
A3: 46174 | B3: 0.25 | C3: Ok | D3: Ok | E3: Ok | F3: Ok | G3: Ok | H3: Ok | I3: Ok | J3: Ok | K3: Ok | L3: Ok | M3: Ok | N3: Not Ok | O3: Not Ok | P3: Not Ok | Q3: Not Ok | R3: Not Ok | S3: Not Ok | T3: Not Ok | U3: Ok | V3: Ok | W3: Not Ok | X3: Ok | Y3: Not Ok | Z3: Not Ok | AA3: Ok | AB3: Not Ok | AC3: Ok | AD3: Ok | AE3: Not Ok | AF3: Ok | AG3: Not Ok | AH3: Not Ok | AI3: Ok | AJ3: Not Ok | AK3: Not Ok | AL3: Ok | AM3: Not Ok | AN3: Not Ok | AO3: Not Ok | AP3: Not Ok | AQ3: Not Ok | AR3: Not Ok | AS3: Not Ok | AT3: Not Ok | AU3: Not Ok | AV3: Ok | AW3: Not Ok | AX3: Ok | AY3: Ok | AZ3: Ok | BA3: Not Ok | BB3: Ok | BC3: Ok | BD3: Not Ok | BE3: Not Ok | BF3: Ok | BG3: Ok | BH3: Ok | BI3: Not Ok | BJ3: Ok | BK3: Not Ok | BL3: Ok | BM3: Not Ok | BN3: Ok | BO3: Ok | BP3: Ok | BQ3: Ok | BR3: CHOMBA | BS3: 23 Gauges on OverCharged position & 9 on Recharge position
B4: 0.75 | C4: Ok | D4: Ok | E4: Ok | F4: Ok | G4: Ok | H4: Ok | I4: Ok | J4: Ok | K4: Ok | L4: Ok | M4: Ok | N4: Not Ok | O4: Not Ok | P4: Not Ok | Q4: Not Ok | R4: Not Ok | S4: Not Ok | T4: Not Ok | U4: Ok | V4: Ok | W4: Not Ok | X4: Ok | Y4: Not Ok | Z4: Not Ok | AA4: Ok | AB4: Not Ok | AC4: Ok | AD4: Ok | AE4: Not Ok | AF4: Ok | AG4: Not Ok | AH4: Not Ok | AI4: Ok | AJ4: Not Ok | AK4: Not Ok | AL4: Ok | AM4: Not Ok | AN4: Not Ok | AO4: Not Ok | AP4: Not Ok | AQ4: Not Ok | AR4: Not Ok | AS4: Not Ok | AT4: Not Ok | AU4: Not Ok | AV4: Ok | AW4: Not Ok | AX4: Ok | AY4: Ok | AZ4: Ok | BA4: Not Ok | BB4: Ok | BC4: Ok | BD4: Not Ok | BE4: Not Ok | BF4: Ok | BG4: Ok | BH4: Ok | BI4: Not Ok | BJ4: Ok | BK4: Not Ok | BL4: Ok | BM4: Not Ok | BN4: Ok | BO4: Ok | BP4: Ok | BQ4: Ok
A6: 46175 | B6: 0.25 | C6: Ok | D6: Ok | E6: Ok | F6: Ok | G6: Ok | H6: Ok | I6: Ok | J6: Ok | K6: Ok | L6: Ok | M6: Ok | N6: Not Ok | O6: Not Ok | P6: Not Ok | Q6: Not Ok | R6: Not Ok | S6: Not Ok | T6: Not Ok | U6: Ok | V6: Ok | W6: Not Ok | X6: Ok | Y6: Not Ok | Z6: Not Ok | AA6: Ok | AB6: Not Ok | AC6: Ok | AD6: Ok | AE6: Not Ok | AF6: Ok | AG6: Not Ok | AH6: Not Ok | AI6: Ok | AJ6: Not Ok | AK6: Not Ok | AL6: Ok | AM6: Not Ok | AN6: Not Ok | AO6: Not Ok | AP6: Not Ok | AQ6: Not Ok | AR6: Not Ok | AS6: Not Ok | AT6: Not Ok | AU6: Not Ok | AV6: Ok | AW6: Not Ok | AX6: Ok | AY6: Ok | AZ6: Ok | BA6: Not Ok | BB6: Ok | BC6: Ok | BD6: Not Ok | BE6: Not Ok | BF6: Ok | BG6: Ok | BH6: Ok | BI6: Not Ok | BJ6: Ok | BK6: Not Ok | BL6: Ok | BM6: Not Ok | BN6: Ok | BO6: Ok | BP6: Ok | BQ6: Ok | BR6: CHOMBA | BS6: 23 Gauges on OverCharged position & 9 on Recharge position
B7: 0.75 | C7: Ok | D7: Ok | E7: Ok | F7: Ok | G7: Ok | H7: Ok | I7: Ok | J7: Ok | K7: Ok | L7: Ok | M7: Ok | N7: Not Ok | O7: Not Ok | P7: Not Ok | Q7: Not Ok | R7: Not Ok | S7: Not Ok | T7: Not Ok | U7: Ok | V7: Ok | W7: Not Ok | X7: Ok | Y7: Not Ok | Z7: Not Ok | AA7: Ok | AB7: Not Ok | AC7: Ok | AD7: Ok | AE7: Not Ok | AF7: Ok | AG7: Not Ok | AH7: Not Ok | AI7: Ok | AJ7: Not Ok | AK7: Not Ok | AL7: Ok | AM7: Not Ok | AN7: Not Ok | AO7: Not Ok | AP7: Not Ok | AQ7: Not Ok | AR7: Not Ok | AS7: Not Ok | AT7: Not Ok | AU7: Not Ok | AV7: Ok | AW7: Not Ok | AX7: Ok | AY7: Ok | AZ7: Ok | BA7: Not Ok | BB7: Ok | BC7: Ok | BD7: Not Ok | BE7: Not Ok | BF7: Ok | BG7: Ok | BH7: Ok | BI7: Not Ok | BJ7: Ok | BK7: Not Ok | BL7: Ok | BM7: Not Ok | BN7: Ok | BO7: Ok | BP7: Ok | BQ7: Ok
A9: 46176 | B9: 0.25 | C9: Ok | D9: Ok | E9: Ok | F9: Ok | G9: Ok | H9: Ok | I9: Ok | J9: Ok | K9: Ok | L9: Ok | M9: Ok | N9: Not Ok | O9: Not Ok | P9: Not Ok | Q9: Not Ok | R9: Not Ok | S9: Not Ok | T9: Not Ok | U9: Ok | V9: Ok | W9: Not Ok | X9: Ok | Y9: Not Ok | Z9: Not Ok | AA9: Ok | AB9: Not Ok | AC9: Ok | AD9: Ok | AE9: Not Ok | AF9: Ok | AG9: Not Ok | AH9: Not Ok | AI9: Ok | AJ9: Not Ok | AK9: Not Ok | AL9: Ok | AM9: Not Ok | AN9: Not Ok | AO9: Not Ok | AP9: Not Ok | AQ9: Not Ok | AR9: Not Ok | AS9: Not Ok | AT9: Not Ok | AU9: Not Ok | AV9: Ok | AW9: Not Ok | AX9: Ok | AY9: Ok | AZ9: Ok | BA9: Not Ok | BB9: Ok | BC9: Ok | BD9: Not Ok | BE9: Not Ok | BF9: Ok | BG9: Ok | BH9: Ok | BI9: Not Ok | BJ9: Ok | BK9: Not Ok | BL9: Ok | BM9: Not Ok | BN9: Ok | BO9: Ok | BP9: Ok | BQ9: Ok | BR9: CHOMBA | BS9: 23 Gauges on OverCharged position & 9 on Recharge position
B10: 0.75 | C10: Ok | D10: Ok | E10: Ok | F10: Ok | G10: Ok | H10: Ok | I10: Ok | J10: Ok | K10: Ok | L10: Ok | M10: Ok | N10: Not Ok | O10: Not Ok | P10: Not Ok | Q10: Not Ok | R10: Not Ok | S10: Not Ok | T10: Not Ok | U10: Ok | V10: Ok | W10: Not Ok | X10: Ok | Y10: Not Ok | Z10: Not Ok | AA10: Ok | AB10: Not Ok | AC10: Ok | AD10: Ok | AE10: Not Ok | AF10: Ok | AG10: Not Ok | AH10: Not Ok | AI10: Ok | AJ10: Not Ok | AK10: Not Ok | AL10: Ok | AM10: Not Ok | AN10: Not Ok | AO10: Not Ok | AP10: Not Ok | AQ10: Not Ok | AR10: Not Ok | AS10: Not Ok | AT10: Not Ok | AU10: Not Ok | AV10: Ok | AW10: Not Ok | AX10: Ok | AY10: Ok | AZ10: Ok | BA10: Not Ok | BB10: Ok | BC10: Ok | BD10: Not Ok | BE10: Not Ok | BF10: Ok | BG10: Ok | BH10: Ok | BI10: Not Ok | BJ10: Ok | BK10: Not Ok | BL10: Ok | BM10: Not Ok | BN10: Ok | BO10: Ok | BP10: Ok | BQ10: Ok
A12: 46177 | B12: 0.25 | C12: Ok | D12: Ok | E12: Ok | F12: Ok | G12: Ok | H12: Ok | I12: Ok | J12: Ok | K12: Ok | L12: Ok | M12: Ok | N12: Not Ok | O12: Not Ok | P12: Not Ok | Q12: Not Ok | R12: Not Ok | S12: Not Ok | T12: Not Ok | U12: Ok | V12: Ok | W12: Not Ok | X12: Ok | Y12: Not Ok | Z12: Not Ok | AA12: Ok | AB12: Not Ok | AC12: Ok | AD12: Ok | AE12: Not Ok | AF12: Ok | AG12: Not Ok | AH12: Not Ok | AI12: Ok | AJ12: Not Ok | AK12: Not Ok | AL12: Ok | AM12: Not Ok | AN12: Not Ok | AO12: Not Ok | AP12: Not Ok | AQ12: Not Ok | AR12: Not Ok | AS12: Not Ok | AT12: Not Ok | AU12: Not Ok | AV12: Ok | AW12: Not Ok | AX12: Ok | AY12: Ok | AZ12: Ok | BA12: Not Ok | BB12: Ok | BC12: Ok | BD12: Not Ok | BE12: Not Ok | BF12: Ok | BG12: Ok | BH12: Ok | BI12: Not Ok | BJ12: Ok | BK12: Not Ok | BL12: Ok | BM12: Not Ok | BN12: Ok | BO12: Ok | BP12: Ok | BQ12: Ok | BR12: CHOMBA | BS12: 23 Gauges on OverCharged position & 9 on Recharge position
B13: 0.75 | C13: Ok | D13: Ok | E13: Ok | F13: Ok | G13: Ok | H13: Ok | I13: Ok | J13: Ok | K13: Ok | L13: Ok | M13: Ok | N13: Not Ok | O13: Not Ok | P13: Not Ok | Q13: Not Ok | R13: Not Ok | S13: Not Ok | T13: Not Ok | U13: Ok | V13: Ok | W13: Not Ok | X13: Ok | Y13: Not Ok | Z13: Not Ok | AA13: Ok | AB13: Not Ok | AC13: Ok | AD13: Ok | AE13: Not Ok | AF13: Ok | AG13: Not Ok | AH13: Not Ok | AI13: Ok | AJ13: Not Ok | AK13: Not Ok | AL13: Ok | AM13: Not Ok | AN13: Not Ok | AO13: Not Ok | AP13: Not Ok | AQ13: Not Ok | AR13: Not Ok | AS13: Not Ok | AT13: Not Ok | AU13: Not Ok | AV13: Ok | AW13: Not Ok | AX13: Ok | AY13: Ok | AZ13: Ok | BA13: Not Ok | BB13: Ok | BC13: Ok | BD13: Not Ok | BE13: Not Ok | BF13: Ok | BG13: Ok | BH13: Ok | BI13: Not Ok | BJ13: Ok | BK13: Not Ok | BL13: Ok | BM13: Not Ok | BN13: Ok | BO13: Ok | BP13: Ok | BQ13: Ok
A15: 46178 | B15: 0.25 | C15: Ok | D15: Ok | E15: Ok | F15: Ok | G15: Ok | H15: Ok | I15: Ok | J15: Ok | K15: Ok | L15: Ok | M15: Ok | N15: Not Ok | O15: Not Ok | P15: Not Ok | Q15: Not Ok | R15: Not Ok | S15: Not Ok | T15: Not Ok | U15: Ok | V15: Ok | W15: Not Ok | X15: Ok | Y15: Not Ok | Z15: Not Ok | AA15: Ok | AB15: Not Ok | AC15: Ok | AD15: Ok | AE15: Not Ok | AF15: Ok | AG15: Not Ok | AH15: Not Ok | AI15: Ok | AJ15: Not Ok | AK15: Not Ok | AL15: Ok | AM15: Not Ok | AN15: Not Ok | AO15: Not Ok | AP15: Not Ok | AQ15: Not Ok | AR15: Not Ok | AS15: Not Ok | AT15: Not Ok | AU15: Not Ok | AV15: Ok | AW15: Not Ok | AX15: Ok | AY15: Ok | AZ15: Ok | BA15: Not Ok | BB15: Ok | BC15: Ok | BD15: Not Ok | BE15: Not Ok | BF15: Ok | BG15: Ok | BH15: Ok | BI15: Not Ok | BJ15: Ok | BK15: Not Ok | BL15: Ok | BM15: Not Ok | BN15: Ok | BO15: Ok | BP15: Ok | BQ15: Ok | BR15: CHOMBA | BS15: 23 Gauges on OverCharged position & 9 on Recharge position
B16: 0.75 | C16: Ok | D16: Ok | E16: Ok | F16: Ok | G16: Ok | H16: Ok | I16: Ok | J16: Ok | K16: Ok | L16: Ok | M16: Ok | N16: Not Ok | O16: Not Ok | P16: Not Ok | Q16: Not Ok | R16: Not Ok | S16: Not Ok | T16: Not Ok | U16: Ok | V16: Ok | W16: Not Ok | X16: Ok | Y16: Not Ok | Z16: Not Ok | AA16: Ok | AB16: Not Ok | AC16: Ok | AD16: Ok | AE16: Not Ok | AF16: Ok | AG16: Not Ok | AH16: Not Ok | AI16: Ok | AJ16: Not Ok | AK16: Not Ok | AL16: Ok | AM16: Not Ok | AN16: Not Ok | AO16: Not Ok | AP16: Not Ok | AQ16: Not Ok | AR16: Not Ok | AS16: Not Ok | AT16: Not Ok | AU16: Not Ok | AV16: Ok | AW16: Not Ok | AX16: Ok | AY16: Ok | AZ16: Ok | BA16: Not Ok | BB16: Ok | BC16: Ok | BD16: Not Ok | BE16: Not Ok | BF16: Ok | BG16: Ok | BH16: Ok | BI16: Not Ok | BJ16: Ok | BK16: Not Ok | BL16: Ok | BM16: Not Ok | BN16: Ok | BO16: Ok | BP16: Ok | BQ16: Ok
A18: 46179 | B18: 0.25 | C18: Ok | D18: Ok | E18: Ok | F18: Ok | G18: Ok | H18: Ok | I18: Ok | J18: Ok | K18: Ok | L18: Ok | M18: Ok | N18: Not Ok | O18: Not Ok | P18: Not Ok | Q18: Not Ok | R18: Not Ok | S18: Not Ok | T18: Not Ok | U18: Ok | V18: Ok | W18: Not Ok | X18: Ok | Y18: Not Ok | Z18: Not Ok | AA18: Ok | AB18: Not Ok | AC18: Ok | AD18: Ok | AE18: Not Ok | AF18: Ok | AG18: Not Ok | AH18: Not Ok | AI18: Ok | AJ18: Not Ok | AK18: Not Ok | AL18: Ok | AM18: Not Ok | AN18: Not Ok | AO18: Not Ok | AP18: Not Ok | AQ18: Not Ok | AR18: Not Ok | AS18: Not Ok | AT18: Not Ok | AU18: Not Ok | AV18: Ok | AW18: Not Ok | AX18: Ok | AY18: Ok | AZ18: Ok | BA18: Not Ok | BB18: Ok | BC18: Ok | BD18: Not Ok | BE18: Not Ok | BF18: Ok | BG18: Ok | BH18: Ok | BI18: Not Ok | BJ18: Ok | BK18: Not Ok | BL18: Ok | BM18: Not Ok | BN18: Ok | BO18: Ok | BP18: Ok | BQ18: Ok | BR18: CHOMBA | BS18: 23 Gauges on OverCharged position & 9 on Recharge position
B19: 0.75 | C19: Ok | D19: Ok | E19: Ok | F19: Ok | G19: Ok | H19: Ok | I19: Ok | J19: Ok | K19: Ok | L19: Ok | M19: Ok | N19: Not Ok | O19: Not Ok | P19: Not Ok | Q19: Not Ok | R19: Not Ok | S19: Not Ok | T19: Not Ok | U19: Ok | V19: Ok | W19: Not Ok | X19: Ok | Y19: Not Ok | Z19: Not Ok | AA19: Ok | AB19: Not Ok | AC19: Ok | AD19: Ok | AE19: Not Ok | AF19: Ok | AG19: Not Ok | AH19: Not Ok | AI19: Ok | AJ19: Not Ok | AK19: Not Ok | AL19: Ok | AM19: Not Ok | AN19: Not Ok | AO19: Not Ok | AP19: Not Ok | AQ19: Not Ok | AR19: Not Ok | AS19: Not Ok | AT19: Not Ok | AU19: Not Ok | AV19: Ok | AW19: Not Ok | AX19: Ok | AY19: Ok | AZ19: Ok | BA19: Not Ok | BB19: Ok | BC19: Ok | BD19: Not Ok | BE19: Not Ok | BF19: Ok | BG19: Ok | BH19: Ok | BI19: Not Ok | BJ19: Ok | BK19: Not Ok | BL19: Ok | BM19: Not Ok | BN19: Ok | BO19: Ok | BP19: Ok | BQ19: Ok
A21: 46180 | B21: 0.25 | C21: Ok | D21: Ok | E21: Ok | F21: Ok | G21: Ok | H21: Ok | I21: Ok | J21: Ok | K21: Ok | L21: Ok | M21: Ok | N21: Not Ok | O21: Not Ok | P21: Not Ok | Q21: Not Ok | R21: Not Ok | S21: Not Ok | T21: Not Ok | U21: Ok | V21: Ok | W21: Not Ok | X21: Ok | Y21: Not Ok | Z21: Not Ok | AA21: Ok | AB21: Not Ok | AC21: Ok | AD21: Ok | AE21: Not Ok | AF21: Ok | AG21: Not Ok | AH21: Not Ok | AI21: Ok | AJ21: Not Ok | AK21: Not Ok | AL21: Ok | AM21: Not Ok | AN21: Not Ok | AO21: Not Ok | AP21: Not Ok | AQ21: Not Ok | AR21: Not Ok | AS21: Not Ok | AT21: Not Ok | AU21: Not Ok | AV21: Ok | AW21: Not Ok | AX21: Ok | AY21: Ok | AZ21: Ok | BA21: Not Ok | BB21: Ok | BC21: Ok | BD21: Not Ok | BE21: Not Ok | BF21: Ok | BG21: Ok | BH21: Ok | BI21: Not Ok | BJ21: Ok | BK21: Not Ok | BL21: Ok | BM21: Not Ok | BN21: Ok | BO21: Ok | BP21: Ok | BQ21: Ok | BR21: CHOMBA | BS21: 23 Gauges on OverCharged position & 9 on Recharge position
B22: 0.75 | C22: Ok | D22: Ok | E22: Ok | F22: Ok | G22: Ok | H22: Ok | I22: Ok | J22: Ok | K22: Ok | L22: Ok | M22: Ok | N22: Not Ok | O22: Not Ok | P22: Not Ok | Q22: Not Ok | R22: Not Ok | S22: Not Ok | T22: Not Ok | U22: Ok | V22: Ok | W22: Not Ok | X22: Ok | Y22: Not Ok | Z22: Not Ok | AA22: Ok | AB22: Not Ok | AC22: Ok | AD22: Ok | AE22: Not Ok | AF22: Ok | AG22: Not Ok | AH22: Not Ok | AI22: Ok | AJ22: Not Ok | AK22: Not Ok | AL22: Ok | AM22: Not Ok | AN22: Not Ok | AO22: Not Ok | AP22: Not Ok | AQ22: Not Ok | AR22: Not Ok | AS22: Not Ok | AT22: Not Ok | AU22: Not Ok | AV22: Ok | AW22: Not Ok | AX22: Ok | AY22: Ok | AZ22: Ok | BA22: Not Ok | BB22: Ok | BC22: Ok | BD22: Not Ok | BE22: Not Ok | BF22: Ok | BG22: Ok | BH22: Ok | BI22: Not Ok | BJ22: Ok | BK22: Not Ok | BL22: Ok | BM22: Not Ok | BN22: Ok | BO22: Ok | BP22: Ok | BQ22: Ok
A24: 46181 | B24: 0.25 | C24: Ok | D24: Ok | E24: Ok | F24: Ok | G24: Ok | H24: Ok | I24: Ok | J24: Ok | K24: Ok | L24: Ok | M24: Ok | N24: Not Ok | O24: Not Ok | P24: Not Ok | Q24: Not Ok | R24: Not Ok | S24: Not Ok | T24: Not Ok | U24: Ok | V24: Ok | W24: Not Ok | X24: Ok | Y24: Not Ok | Z24: Not Ok | AA24: Ok | AB24: Not Ok | AC24: Ok | AD24: Ok | AE24: Not Ok | AF24: Ok | AG24: Not Ok | AH24: Not Ok | AI24: Ok | AJ24: Not Ok | AK24: Not Ok | AL24: Ok | AM24: Not Ok | AN24: Not Ok | AO24: Not Ok | AP24: Not Ok | AQ24: Not Ok | AR24: Not Ok | AS24: Not Ok | AT24: Not Ok | AU24: Not Ok | AV24: Ok | AW24: Not Ok | AX24: Ok | AY24: Ok | AZ24: Ok | BA24: Not Ok | BB24: Ok | BC24: Ok | BD24: Not Ok | BE24: Not Ok | BF24: Ok | BG24: Ok | BH24: Ok | BI24: Not Ok | BJ24: Ok | BK24: Not Ok | BL24: Ok | BM24: Not Ok | BN24: Ok | BO24: Ok | BP24: Ok | BQ24: Ok | BR24: PETER | BS24: 23 Gauges on OverCharged position & 9 on Recharge position
B25: 0.75 | C25: Ok | D25: Ok | E25: Ok | F25: Ok | G25: Ok | H25: Ok | I25: Ok | J25: Ok | K25: Ok | L25: Ok | M25: Ok | N25: Not Ok | O25: Not Ok | P25: Not Ok | Q25: Not Ok | R25: Not Ok | S25: Not Ok | T25: Not Ok | U25: Ok | V25: Ok | W25: Not Ok | X25: Ok | Y25: Not Ok | Z25: Not Ok | AA25: Ok | AB25: Not Ok | AC25: Ok | AD25: Ok | AE25: Not Ok | AF25: Ok | AG25: Not Ok | AH25: Not Ok | AI25: Ok | AJ25: Not Ok | AK25: Not Ok | AL25: Ok | AM25: Not Ok | AN25: Not Ok | AO25: Not Ok | AP25: Not Ok | AQ25: Not Ok | AR25: Not Ok | AS25: Not Ok | AT25: Not Ok | AU25: Not Ok | AV25: Ok | AW25: Not Ok | AX25: Ok | AY25: Ok | AZ25: Ok | BA25: Not Ok | BB25: Ok | BC25: Ok | BD25: Not Ok | BE25: Not Ok | BF25: Ok | BG25: Ok | BH25: Ok | BI25: Not Ok | BJ25: Ok | BK25: Not Ok | BL25: Ok | BM25: Not Ok | BN25: Ok | BO25: Ok | BP25: Ok | BQ25: Ok
A27: 46182 | B27: 0.25 | C27: Ok | D27: Ok | E27: Ok | F27: Ok | G27: Ok | H27: Ok | I27: Ok | J27: Ok | K27: Ok | L27: Ok | M27: Ok | N27: Not Ok | O27: Not Ok | P27: Not Ok | Q27: Not Ok | R27: Not Ok | S27: Not Ok | T27: Not Ok | U27: Ok | V27: Ok | W27: Not Ok | X27: Ok | Y27: Not Ok | Z27: Not Ok | AA27: Ok | AB27: Not Ok | AC27: Ok | AD27: Ok | AE27: Not Ok | AF27: Ok | AG27: Not Ok | AH27: Not Ok | AI27: Ok | AJ27: Not Ok | AK27: Not Ok | AL27: Ok | AM27: Not Ok | AN27: Not Ok | AO27: Not Ok | AP27: Not Ok | AQ27: Not Ok | AR27: Not Ok | AS27: Not Ok | AT27: Not Ok | AU27: Not Ok | AV27: Ok | AW27: Not Ok | AX27: Ok | AY27: Ok | AZ27: Ok | BA27: Not Ok | BB27: Ok | BC27: Ok | BD27: Not Ok | BE27: Not Ok | BF27: Ok | BG27: Ok | BH27: Ok | BI27: Not Ok | BJ27: Ok | BK27: Not Ok | BL27: Ok | BM27: Not Ok | BN27: Ok | BO27: Ok | BP27: Ok | BQ27: Ok | BR27: PETER | BS27: 23 Gauges on OverCharged position & 9 on Recharge position
B28: 0.75 | C28: Ok | D28: Ok | E28: Ok | F28: Ok | G28: Ok | H28: Ok | I28: Ok | J28: Ok | K28: Ok | L28: Ok | M28: Ok | N28: Not Ok | O28: Not Ok | P28: Not Ok | Q28: Not Ok | R28: Not Ok | S28: Not Ok | T28: Not Ok | U28: Ok | V28: Ok | W28: Not Ok | X28: Ok | Y28: Not Ok | Z28: Not Ok | AA28: Ok | AB28: Not Ok | AC28: Ok | AD28: Ok | AE28: Not Ok | AF28: Ok | AG28: Not Ok | AH28: Not Ok | AI28: Ok | AJ28: Not Ok | AK28: Not Ok | AL28: Ok | AM28: Not Ok | AN28: Not Ok | AO28: Not Ok | AP28: Not Ok | AQ28: Not Ok | AR28: Not Ok | AS28: Not Ok | AT28: Not Ok | AU28: Not Ok | AV28: Ok | AW28: Not Ok | AX28: Ok | AY28: Ok | AZ28: Ok | BA28: Not Ok | BB28: Ok | BC28: Ok | BD28: Not Ok | BE28: Not Ok | BF28: Ok | BG28: Ok | BH28: Ok | BI28: Not Ok | BJ28: Ok | BK28: Not Ok | BL28: Ok | BM28: Not Ok | BN28: Ok | BO28: Ok | BP28: Ok | BQ28: Ok
A30: 46183 | B30: 0.25 | C30: Ok | D30: Ok | E30: Ok | F30: Ok | G30: Ok | H30: Ok | I30: Ok | J30: Ok | K30: Ok | L30: Ok | M30: Ok | N30: Not Ok | O30: Not Ok | P30: Not Ok | Q30: Not Ok | R30: Not Ok | S30: Not Ok | T30: Not Ok | U30: Ok | V30: Ok | W30: Not Ok | X30: Ok | Y30: Not Ok | Z30: Not Ok | AA30: Ok | AB30: Not Ok | AC30: Ok | AD30: Ok | AE30: Not Ok | AF30: Ok | AG30: Not Ok | AH30: Not Ok | AI30: Ok | AJ30: Not Ok | AK30: Not Ok | AL30: Ok | AM30: Not Ok | AN30: Not Ok | AO30: Not Ok | AP30: Not Ok | AQ30: Not Ok | AR30: Not Ok | AS30: Not Ok | AT30: Not Ok | AU30: Not Ok | AV30: Ok | AW30: Not Ok | AX30: Ok | AY30: Ok | AZ30: Ok | BA30: Not Ok | BB30: Ok | BC30: Ok | BD30: Not Ok | BE30: Not Ok | BF30: Ok | BG30: Ok | BH30: Ok | BI30: Not Ok | BJ30: Ok | BK30: Not Ok | BL30: Ok | BM30: Not Ok | BN30: Ok | BO30: Ok | BP30: Ok | BQ30: Ok | BR30: PETER | BS30: 23 Gauges on OverCharged position & 9 on Recharge position
B31: 0.75 | C31: Ok | D31: Ok | E31: Ok | F31: Ok | G31: Ok | H31: Ok | I31: Ok | J31: Ok | K31: Ok | L31: Ok | M31: Ok | N31: Not Ok | O31: Not Ok | P31: Not Ok | Q31: Not Ok | R31: Not Ok | S31: Not Ok | T31: Not Ok | U31: Ok | V31: Ok | W31: Not Ok | X31: Ok | Y31: Not Ok | Z31: Not Ok | AA31: Ok | AB31: Not Ok | AC31: Ok | AD31: Ok | AE31: Not Ok | AF31: Ok | AG31: Not Ok | AH31: Not Ok | AI31: Ok | AJ31: Not Ok | AK31: Not Ok | AL31: Ok | AM31: Not Ok | AN31: Not Ok | AO31: Not Ok | AP31: Not Ok | AQ31: Not Ok | AR31: Not Ok | AS31: Not Ok | AT31: Not Ok | AU31: Not Ok | AV31: Ok | AW31: Not Ok | AX31: Ok | AY31: Ok | AZ31: Ok | BA31: Not Ok | BB31: Ok | BC31: Ok | BD31: Not Ok | BE31: Not Ok | BF31: Ok | BG31: Ok | BH31: Ok | BI31: Not Ok | BJ31: Ok | BK31: Not Ok | BL31: Ok | BM31: Not Ok | BN31: Ok | BO31: Ok | BP31: Ok | BQ31: Ok
A33: 46184 | B33: 0.25 | C33: Ok | D33: Ok | E33: Ok | F33: Ok | G33: Ok | H33: Ok | I33: Ok | J33: Ok | K33: Ok | L33: Ok | M33: Ok | N33: Not Ok | O33: Not Ok | P33: Not Ok | Q33: Not Ok | R33: Not Ok | S33: Not Ok | T33: Not Ok | U33: Ok | V33: Ok | W33: Not Ok | X33: Ok | Y33: Not Ok | Z33: Not Ok | AA33: Ok | AB33: Not Ok | AC33: Ok | AD33: Ok | AE33: Not Ok | AF33: Ok | AG33: Not Ok | AH33: Not Ok | AI33: Ok | AJ33: Not Ok | AK33: Not Ok | AL33: Ok | AM33: Not Ok | AN33: Not Ok | AO33: Not Ok | AP33: Not Ok | AQ33: Not Ok | AR33: Not Ok | AS33: Not Ok | AT33: Not Ok | AU33: Not Ok | AV33: Ok | AW33: Not Ok | AX33: Ok | AY33: Ok | AZ33: Ok | BA33: Not Ok | BB33: Ok | BC33: Ok | BD33: Not Ok | BE33: Not Ok | BF33: Ok | BG33: Ok | BH33: Ok | BI33: Not Ok | BJ33: Ok | BK33: Not Ok | BL33: Ok | BM33: Not Ok | BN33: Ok | BO33: Ok | BP33: Ok | BQ33: Ok | BR33: PETER | BS33: 23 Gauges on OverCharged position & 9 on Recharge position
B34: 0.75 | C34: Ok | D34: Ok | E34: Ok | F34: Ok | G34: Ok | H34: Ok | I34: Ok | J34: Ok | K34: Ok | L34: Ok | M34: Ok | N34: Not Ok | O34: Not Ok | P34: Not Ok | Q34: Not Ok | R34: Not Ok | S34: Not Ok | T34: Not Ok | U34: Ok | V34: Ok | W34: Not Ok | X34: Ok | Y34: Not Ok | Z34: Not Ok | AA34: Ok | AB34: Not Ok | AC34: Ok | AD34: Ok | AE34: Not Ok | AF34: Ok | AG34: Not Ok | AH34: Not Ok | AI34: Ok | AJ34: Not Ok | AK34: Not Ok | AL34: Ok | AM34: Not Ok | AN34: Not Ok | AO34: Not Ok | AP34: Not Ok | AQ34: Not Ok | AR34: Not Ok | AS34: Not Ok | AT34: Not Ok | AU34: Not Ok | AV34: Ok | AW34: Not Ok | AX34: Ok | AY34: Ok | AZ34: Ok | BA34: Not Ok | BB34: Ok | BC34: Ok | BD34: Not Ok | BE34: Not Ok | BF34: Ok | BG34: Ok | BH34: Ok | BI34: Not Ok | BJ34: Ok | BK34: Not Ok | BL34: Ok | BM34: Not Ok | BN34: Ok | BO34: Ok | BP34: Ok | BQ34: Ok
A36: 46185 | B36: 0.25 | C36: Ok | D36: Ok | E36: Ok | F36: Ok | G36: Ok | H36: Ok | I36: Ok | J36: Ok | K36: Ok | L36: Ok | M36: Ok | N36: Not Ok | O36: Not Ok | P36: Not Ok | Q36: Not Ok | R36: Not Ok | S36: Not Ok | T36: Not Ok | U36: Ok | V36: Ok | W36: Not Ok | X36: Ok | Y36: Not Ok | Z36: Not Ok | AA36: Ok | AB36: Not Ok | AC36: Ok | AD36: Ok | AE36: Not Ok | AF36: Ok | AG36: Not Ok | AH36: Not Ok | AI36: Ok | AJ36: Not Ok | AK36: Not Ok | AL36: Ok | AM36: Not Ok | AN36: Not Ok | AO36: Not Ok | AP36: Not Ok | AQ36: Not Ok | AR36: Not Ok | AS36: Not Ok | AT36: Not Ok | AU36: Not Ok | AV36: Ok | AW36: Not Ok | AX36: Ok | AY36: Ok | AZ36: Ok | BA36: Not Ok | BB36: Ok | BC36: Ok | BD36: Not Ok | BE36: Not Ok | BF36: Ok | BG36: Ok | BH36: Ok | BI36: Not Ok | BJ36: Ok | BK36: Not Ok | BL36: Ok | BM36: Not Ok | BN36: Ok | BO36: Ok | BP36: Ok | BQ36: Ok | BR36: PETER | BS36: 23 Gauges on OverCharged position & 9 on Recharge position
B37: 0.75 | C37: Ok | D37: Ok | E37: Ok | F37: Ok | G37: Ok | H37: Ok | I37: Ok | J37: Ok | K37: Ok | L37: Ok | M37: Ok | N37: Not Ok | O37: Not Ok | P37: Not Ok | Q37: Not Ok | R37: Not Ok | S37: Not Ok | T37: Not Ok | U37: Ok | V37: Ok | W37: Not Ok | X37: Ok | Y37: Not Ok | Z37: Not Ok | AA37: Ok | AB37: Not Ok | AC37: Ok | AD37: Ok | AE37: Not Ok | AF37: Ok | AG37: Not Ok | AH37: Not Ok | AI37: Ok | AJ37: Not Ok | AK37: Not Ok | AL37: Ok | AM37: Not Ok | AN37: Not Ok | AO37: Not Ok | AP37: Not Ok | AQ37: Not Ok | AR37: Not Ok | AS37: Not Ok | AT37: Not Ok | AU37: Not Ok | AV37: Ok | AW37: Not Ok | AX37: Ok | AY37: Ok | AZ37: Ok | BA37: Not Ok | BB37: Ok | BC37: Ok | BD37: Not Ok | BE37: Not Ok | BF37: Ok | BG37: Ok | BH37: Ok | BI37: Not Ok | BJ37: Ok | BK37: Not Ok | BL37: Ok | BM37: Not Ok | BN37: Ok | BO37: Ok | BP37: Ok | BQ37: Ok
A39: 46186 | B39: 0.25 | C39: Ok | D39: Ok | E39: Ok | F39: Ok | G39: Ok | H39: Ok | I39: Ok | J39: Ok | K39: Ok | L39: Ok | M39: Ok | N39: Not Ok | O39: Not Ok | P39: Not Ok | Q39: Not Ok | R39: Not Ok | S39: Not Ok | T39: Not Ok | U39: Ok | V39: Ok | W39: Not Ok | X39: Ok | Y39: Not Ok | Z39: Not Ok | AA39: Ok | AB39: Not Ok | AC39: Ok | AD39: Ok | AE39: Not Ok | AF39: Ok | AG39: Not Ok | AH39: Not Ok | AI39: Ok | AJ39: Not Ok | AK39: Not Ok | AL39: Ok | AM39: Not Ok | AN39: Not Ok | AO39: Not Ok | AP39: Not Ok | AQ39: Not Ok | AR39: Not Ok | AS39: Not Ok | AT39: Not Ok | AU39: Not Ok | AV39: Ok | AW39: Not Ok | AX39: Ok | AY39: Ok | AZ39: Ok | BA39: Not Ok | BB39: Ok | BC39: Ok | BD39: Not Ok | BE39: Not Ok | BF39: Ok | BG39: Ok | BH39: Ok | BI39: Not Ok | BJ39: Ok | BK39: Not Ok | BL39: Ok | BM39: Not Ok | BN39: Ok | BO39: Ok | BP39: Ok | BQ39: Ok | BR39: PETER | BS39: 23 Gauges on OverCharged position & 9 on Recharge position
B40: 0.75 | C40: Ok | D40: Ok | E40: Ok | F40: Ok | G40: Ok | H40: Ok | I40: Ok | J40: Ok | K40: Ok | L40: Ok | M40: Ok | N40: Not Ok | O40: Not Ok | P40: Not Ok | Q40: Not Ok | R40: Not Ok | S40: Not Ok | T40: Not Ok | U40: Ok | V40: Ok | W40: Not Ok | X40: Ok | Y40: Not Ok | Z40: Not Ok | AA40: Ok | AB40: Not Ok | AC40: Ok | AD40: Ok | AE40: Not Ok | AF40: Ok | AG40: Not Ok | AH40: Not Ok | AI40: Ok | AJ40: Not Ok | AK40: Not Ok | AL40: Ok | AM40: Not Ok | AN40: Not Ok | AO40: Not Ok | AP40: Not Ok | AQ40: Not Ok | AR40: Not Ok | AS40: Not Ok | AT40: Not Ok | AU40: Not Ok | AV40: Ok | AW40: Not Ok | AX40: Ok | AY40: Ok | AZ40: Ok | BA40: Not Ok | BB40: Ok | BC40: Ok | BD40: Not Ok | BE40: Not Ok | BF40: Ok | BG40: Ok | BH40: Ok | BI40: Not Ok | BJ40: Ok | BK40: Not Ok | BL40: Ok | BM40: Not Ok | BN40: Ok | BO40: Ok | BP40: Ok | BQ40: Ok
A42: 46187 | B42: 0.25 | C42: Ok | D42: Ok | E42: Ok | F42: Ok | G42: Ok | H42: Ok | I42: Ok | J42: Ok | K42: Ok | L42: Ok | M42: Ok | N42: Not Ok | O42: Not Ok | P42: Not Ok | Q42: Not Ok | R42: Not Ok | S42: Not Ok | T42: Not Ok | U42: Ok | V42: Ok | W42: Not Ok | X42: Ok | Y42: Not Ok | Z42: Not Ok | AA42: Ok | AB42: Not Ok | AC42: Ok | AD42: Ok | AE42: Not Ok | AF42: Ok | AG42: Not Ok | AH42: Not Ok | AI42: Ok | AJ42: Not Ok | AK42: Not Ok | AL42: Ok | AM42: Not Ok | AN42: Not Ok | AO42: Not Ok | AP42: Not Ok | AQ42: Not Ok | AR42: Not Ok | AS42: Not Ok | AT42: Not Ok | AU42: Not Ok | AV42: Ok | AW42: Not Ok | AX42: Ok | AY42: Ok | AZ42: Ok | BA42: Not Ok | BB42: Ok | BC42: Ok | BD42: Not Ok | BE42: Not Ok | BF42: Ok | BG42: Ok | BH42: Ok | BI42: Not Ok | BJ42: Ok | BK42: Not Ok | BL42: Ok | BM42: Not Ok | BN42: Ok | BO42: Ok | BP42: Ok | BQ42: Ok | BR42: PETER | BS42: 23 Gauges on OverCharged position & 9 on Recharge position
B43: 0.75 | C43: Ok | D43: Ok | E43: Ok | F43: Ok | G43: Ok | H43: Ok | I43: Ok | J43: Ok | K43: Ok | L43: Ok | M43: Ok | N43: Not Ok | O43: Not Ok | P43: Not Ok | Q43: Not Ok | R43: Not Ok | S43: Not Ok | T43: Not Ok | U43: Ok | V43: Ok | W43: Not Ok | X43: Ok | Y43: Not Ok | Z43: Not Ok | AA43: Ok | AB43: Not Ok | AC43: Ok | AD43: Ok | AE43: Not Ok | AF43: Ok | AG43: Not Ok | AH43: Not Ok | AI43: Ok | AJ43: Not Ok | AK43: Not Ok | AL43: Ok | AM43: Not Ok | AN43: Not Ok | AO43: Not Ok | AP43: Not Ok | AQ43: Not Ok | AR43: Not Ok | AS43: Not Ok | AT43: Not Ok | AU43: Not Ok | AV43: Ok | AW43: Not Ok | AX43: Ok | AY43: Ok | AZ43: Ok | BA43: Not Ok | BB43: Ok | BC43: Ok | BD43: Not Ok | BE43: Not Ok | BF43: Ok | BG43: Ok | BH43: Ok | BI43: Not Ok | BJ43: Ok | BK43: Not Ok | BL43: Ok | BM43: Not Ok | BN43: Ok | BO43: Ok | BP43: Ok | BQ43: Ok
A45: 46188 | B45: 0.25 | C45: Ok | D45: Ok | E45: Ok | F45: Ok | G45: Ok | H45: Ok | I45: Ok | J45: Ok | K45: Ok | L45: Ok | M45: Ok | N45: Not Ok | O45: Not Ok | P45: Not Ok | Q45: Not Ok | R45: Not Ok | S45: Not Ok | T45: Not Ok | U45: Ok | V45: Ok | W45: Not Ok | X45: Ok | Y45: Not Ok | Z45: Not Ok | AA45: Ok | AB45: Not Ok | AC45: Ok | AD45: Ok | AE45: Not Ok | AF45: Ok | AG45: Not Ok | AH45: Not Ok | AI45: Ok | AJ45: Not Ok | AK45: Not Ok | AL45: Ok | AM45: Not Ok | AN45: Not Ok | AO45: Not Ok | AP45: Not Ok | AQ45: Not Ok | AR45: Not Ok | AS45: Not Ok | AT45: Not Ok | AU45: Not Ok | AV45: Ok | AW45: Not Ok | AX45: Ok | AY45: Ok | AZ45: Ok | BA45: Not Ok | BB45: Ok | BC45: Ok | BD45: Not Ok | BE45: Not Ok | BF45: Ok | BG45: Ok | BH45: Ok | BI45: Not Ok | BJ45: Ok | BK45: Not Ok | BL45: Ok | BM45: Not Ok | BN45: Ok | BO45: Ok | BP45: Ok | BQ45: Ok | BR45: CHOMBA | BS45: 23 Gauges on OverCharged position & 9 on Recharge position
B46: 0.75 | C46: Ok | D46: Ok | E46: Ok | F46: Ok | G46: Ok | H46: Ok | I46: Ok | J46: Ok | K46: Ok | L46: Ok | M46: Ok | N46: Not Ok | O46: Not Ok | P46: Not Ok | Q46: Not Ok | R46: Not Ok | S46: Not Ok | T46: Not Ok | U46: Ok | V46: Ok | W46: Not Ok | X46: Ok | Y46: Not Ok | Z46: Not Ok | AA46: Ok | AB46: Not Ok | AC46: Ok | AD46: Ok | AE46: Not Ok | AF46: Ok | AG46: Not Ok | AH46: Not Ok | AI46: Ok | AJ46: Not Ok | AK46: Not Ok | AL46: Ok | AM46: Not Ok | AN46: Not Ok | AO46: Not Ok | AP46: Not Ok | AQ46: Not Ok | AR46: Not Ok | AS46: Not Ok | AT46: Not Ok | AU46: Not Ok | AV46: Ok | AW46: Not Ok | AX46: Ok | AY46: Ok | AZ46: Ok | BA46: Not Ok | BB46: Ok | BC46: Ok | BD46: Not Ok | BE46: Not Ok | BF46: Ok | BG46: Ok | BH46: Ok | BI46: Not Ok | BJ46: Ok | BK46: Not Ok | BL46: Ok | BM46: Not Ok | BN46: Ok | BO46: Ok | BP46: Ok | BQ46: Ok
A48: 46189 | B48: 0.25 | C48: Ok | D48: Ok | E48: Ok | F48: Ok | G48: Ok | H48: Ok | I48: Ok | J48: Ok | K48: Ok | L48: Ok | M48: Ok | N48: Not Ok | O48: Not Ok | P48: Not Ok | Q48: Not Ok | R48: Not Ok | S48: Not Ok | T48: Not Ok | U48: Ok | V48: Ok | W48: Not Ok | X48: Ok | Y48: Not Ok | Z48: Not Ok | AA48: Ok | AB48: Not Ok | AC48: Ok | AD48: Ok | AE48: Not Ok | AF48: Ok | AG48: Not Ok | AH48: Not Ok | AI48: Ok | AJ48: Not Ok | AK48: Not Ok | AL48: Ok | AM48: Not Ok | AN48: Not Ok | AO48: Not Ok | AP48: Not Ok | AQ48: Not Ok | AR48: Not Ok | AS48: Not Ok | AT48: Not Ok | AU48: Not Ok | AV48: Ok | AW48: Not Ok | AX48: Ok | AY48: Ok | AZ48: Ok | BA48: Not Ok | BB48: Ok | BC48: Ok | BD48: Not Ok | BE48: Not Ok | BF48: Ok | BG48: Ok | BH48: Ok | BI48: Not Ok | BJ48: Ok | BK48: Not Ok | BL48: Ok | BM48: Not Ok | BN48: Ok | BO48: Ok | BP48: Ok | BQ48: Ok | BR48: CHOMBA | BS48: 23 Gauges on OverCharged position & 9 on Recharge position
B49: 0.75 | C49: Ok | D49: Ok | E49: Ok | F49: Ok | G49: Ok | H49: Ok | I49: Ok | J49: Ok | K49: Ok | L49: Ok | M49: Ok | N49: Not Ok | O49: Not Ok | P49: Not Ok | Q49: Not Ok | R49: Not Ok | S49: Not Ok | T49: Not Ok | U49: Ok | V49: Ok | W49: Not Ok | X49: Ok | Y49: Not Ok | Z49: Not Ok | AA49: Ok | AB49: Not Ok | AC49: Ok | AD49: Ok | AE49: Not Ok | AF49: Ok | AG49: Not Ok | AH49: Not Ok | AI49: Ok | AJ49: Not Ok | AK49: Not Ok | AL49: Ok | AM49: Not Ok | AN49: Not Ok | AO49: Not Ok | AP49: Not Ok | AQ49: Not Ok | AR49: Not Ok | AS49: Not Ok | AT49: Not Ok | AU49: Not Ok | AV49: Ok | AW49: Not Ok | AX49: Ok | AY49: Ok | AZ49: Ok | BA49: Not Ok | BB49: Ok | BC49: Ok | BD49: Not Ok | BE49: Not Ok | BF49: Ok | BG49: Ok | BH49: Ok | BI49: Not Ok | BJ49: Ok | BK49: Not Ok | BL49: Ok | BM49: Not Ok | BN49: Ok | BO49: Ok | BP49: Ok | BQ49: Ok
A51: 46190 | B51: 0.25
B52: 0.75
A54: 46191 | B54: 0.25
B55: 0.75
A57: 46192 | B57: 0.25
B58: 0.75
...

Sheet 1
A1: Switch Power & Room temperature Log Sheet | BV1: 46174
A2: Zesco Load Details | N2: DG Load Details | AF2: Ground Floor | BV2: First Floor | CA2: Second Floor | CB2: Load On | CC2: Shift Tech
AF3: Inverter Readings | BF3: Rectifier Readings | BN3: Temperature in Centigrade | BZ3: Condition
A4: Time | B4: Load On Grid in AMPs | E4: Grid Voltage Line to Line | H4: Grid frequency | I4: Grid Power Status ON/ OFF | J4: Grid Off Time | K4: Grid Restored Time | L4: Grid off Duration | M4: Site Load ( ZESCO Or Generator) in kw | N4: Load On DG in AMPs | Q4: DG Voltage Line to Line | T4: DG-1 Run Hrs | U4: DG 1 Battery Voltage | V4: Charged Status (Color) | W4: DG-2 Run Hrs | X4: DG 2 Battery Voltage | Y4: Charged Status (Color) | Z4: DG-3 Run Hrs | AA4: DG 3 Battery Voltage | AB4: Charged Status (Color) | AC4: DG-4 Run Hrs | AD4: DG 4 Battery Voltage | AE4: Charged Status (Color) | AF4: UPS1-POWER PLANT ROOM-1 | AS4: UPS2-POWER PLANT ROOM-2 | BF4: Rectifier 1 - Voltage / Amps | BI4: Used Percentage | BJ4: Rectifier 2 - Voltage / Amps | BM4: Used Percentage | BN4: Room-1 Server & IT | BP4: Media Room | BR4: Power Room-1 | BT4: Power Room-2 | BV4: Room-1 | BX4: Room-2 | BZ4: Work Station | CA4: FM 200 Panel / WDS/Vesda Status
B5: R | C5: Y | D5: B | E5: R | F5: Y | G5: B | H5: HZ | N5: R | O5: Y | P5: B | Q5: R | R5: Y | S5: B | AF5: Output Load KW | AG5: Used Capacity | AH5: Battery Charge % | AI5: Battery Voltage (V) | AJ5: Load Current-A ( A) | AK5: Load Current-B ( A) | AL5: Load Current-C ( A) | AM5: Load Phase -A % | AN5: Load Phase -B % | AO5: Load Phase -C % | AP5: Output Voltage-A ( V) | AQ5: Output Voltage-B ( V) | AR5: Output Voltage-C ( V) | AS5: Output Load KW | AT5: Used Capacity | AU5: Battery Charge % | AV5: Battery Voltage (V) | AW5: Load Current-A ( A) | AX5: Load Current-B ( A) | AY5: Load Current-C ( A) | AZ5: Load Phase -A % | BA5: Load Phase -B % | BB5: Load Phase -C % | BC5: Output Voltage-A ( V) | BD5: Output Voltage-B ( V) | BE5: Output Voltage-C ( V) | BF5: DC Volatge | BG5: Current | BH5: Battery charge status | BJ5: DC Volatge | BK5: Current | BL5: Battery charge status | BN5: Temp | BO5: Hum | BP5: Temp | BQ5: Hum | BR5: Temp | BS5: Hum | BT5: Temp | BU5: Hum | BV5: Temp | BW5: Hum | BX5: Temp | BY5: Hum
A6: 0 | CE6: 100
A7: 0.041666667 | CE7: 40
A8: 0.083333333 | CE8: 200
A9: 0.125 | CE9: 210
A10: 0.16666667 | CE10: 210
A11: 0.20833333
A12: 0.25
A13: 0.29166667
A14: 0.33333333
A15: 0.375
A16: 0.41666667
A17: 0.45833333
A18: 0.5
A19: 0.54166667
A20: 0.58333333
A21: 0.625
A22: 0.66666667
... A29: 0.95833333
B31: Average | C31: Maximum | L31: Average | M31: =AVERAGE(M6:M29) -> #DIV/0! | BE31: Average | BF31: =AVERAGE(BF6:BF29) -> #DIV/0! | BG31: =AVERAGE(BG6:BG29) -> #DIV/0! | BJ31: =AVERAGE(BJ6:BJ29) -> #DIV/0! | BK31: =AVERAGE(BK6:BK29) -> #DIV/0! | BN31: =AVERAGE(BN6:BN29) -> #DIV/0! | BO31: =MAX(BN6:BN29) -> 0 | BP31: =MIN(BN6:BN29) -> 0 | BQ31: =AVERAGE(BO6:BO29) -> #DIV/0! | BR31: =MAX(BO6:BO29) -> 0 | BS31: =MIN(BO6:BO29) -> 0
A32: UPS: | B32: =AF32+AS32 -> #DIV/0! | C32: =AF33+AS33 -> 0 | L32: Max | M32: =MAX(M6:M29) -> 0 | AE32: Avg | AF32: =AVERAGE(AF6:AF29) -> #DIV/0! | AR32: Avg | AS32: =AVERAGE(AS6:AS29) -> #DIV/0! | BE32: Max | BF32: =MAX(BF6:BF29) -> 0 | BG32: =MAX(BG6:BG29) -> 0 | BH32: =BF31*BG31 -> #DIV/0! | BJ32: =MAX(BJ6:BJ29) -> 0 | BK32: =MAX(BK6:BK29) -> 0 | BL32: =BJ31*BK31 -> #DIV/0!
A33: Rectifier: | B33: =(BH32+BL32)/1000 -> #DIV/0! | C33: =(BH33+BL33)/1000 -> 0 | AE33: Max | AF33: =MAX(AF6:AF29) -> 0 | AR33: Max | AS33: =MAX(AS6:AS29) -> 0 | BH33: =BF32*BG32 -> 0 | BL33: =BJ32*BK32 -> 0
A39: Technician signature | R39: Engineer signature
A45: DAILY DIARY
A46: Date | B46: Time | C46: Observations &Activities done on the duty

Sheet 2
A1: Switch Power & Room temperature Log Sheet | BV1: ='1'!BV1:CC1+1 -> 46175
A2: Zesco Load Details | N2: DG Load Details | AF2: Ground Floor | BV2: First Floor | CA2: Second Floor | CB2: Load On | CC2: Shift Tech
AF3: Inverter Readings | BF3: Rectifier Readings | BN3: Temperature in Centigrade | BZ3: Condition
A4: Time | B4: Load On Grid in AMPs | E4: Grid Voltage Line to Line | H4: Grid frequency | I4: Grid Power Status ON/ OFF | J4: Grid Off Time | K4: Grid Restored Time | L4: Grid off Duration | M4: Site Load ( ZESCO Or Generator) in kw | N4: Load On DG in AMPs | Q4: DG Voltage Line to Line | T4: DG-1 Run Hrs | U4: DG 1 Battery Voltage | V4: Charged Status (Color) | W4: DG-2 Run Hrs | X4: DG 2 Battery Voltage | Y4: Charged Status (Color) | Z4: DG-3 Run Hrs | AA4: DG 3 Battery Voltage | AB4: Charged Status (Color) | AC4: DG-4 Run Hrs | AD4: DG 4 Battery Voltage | AE4: Charged Status (Color) | AF4: UPS1-POWER PLANT ROOM-1 | AS4: UPS2-POWER PLANT ROOM-2 | BF4: Rectifier 1 - Voltage / Amps | BI4: Used Percentage | BJ4: Rectifier 2 - Voltage / Amps | BM4: Used Percentage | BN4: Room-1 Server & IT | BP4: Media Room | BR4: Power Room-1 | BT4: Power Room-2 | BV4: Room-1 | BX4: Room-2 | BZ4: Work Station | CA4: FM 200 Panel / WDS/Vesda Status
B5: R | C5: Y | D5: B | E5: R | F5: Y | G5: B | H5: HZ | N5: R | O5: Y | P5: B | Q5: R | R5: Y | S5: B | AF5: Output Load KW | AG5: Used Capacity | AH5: Battery Charge % | AI5: Battery Voltage (V) | AJ5: Load Current-A ( A) | AK5: Load Current-B ( A) | AL5: Load Current-C ( A) | AM5: Load Phase -A % | AN5: Load Phase -B % | AO5: Load Phase -C % | AP5: Output Voltage-A ( V) | AQ5: Output Voltage-B ( V) | AR5: Output Voltage-C ( V) | AS5: Output Load KW | AT5: Used Capacity | AU5: Battery Charge % | AV5: Battery Voltage (V) | AW5: Load Current-A ( A) | AX5: Load Current-B ( A) | AY5: Load Current-C ( A) | AZ5: Load Phase -A % | BA5: Load Phase -B % | BB5: Load Phase -C % | BC5: Output Voltage-A ( V) | BD5: Output Voltage-B ( V) | BE5: Output Voltage-C ( V) | BF5: DC Volatge | BG5: Current | BH5: Battery charge status | BJ5: DC Volatge | BK5: Current | BL5: Battery charge status | BN5: Temp | BO5: Hum | BP5: Temp | BQ5: Hum | BR5: Temp | BS5: Hum | BT5: Temp | BU5: Hum | BV5: Temp | BW5: Hum | BX5: Temp | BY5: Hum
A6: 0
A7: 0.041666667
A8: 0.083333333
A9: 0.125
A10: 0.16666667
A11: 0.20833333
A12: 0.25
A13: 0.29166667
A14: 0.33333333
A15: 0.375
A16: 0.41666667
A17: 0.45833333
... A29: 0.95833333
B31: Average | C31: Maximum | L31: Average | M31: =AVERAGE(M6:M29) -> #DIV/0! | BE31: Average | BF31: =AVERAGE(BF6:BF29) -> #DIV/0! | BG31: =AVERAGE(BG6:BG29) -> #DIV/0! | BJ31: =AVERAGE(BJ6:BJ29) -> #DIV/0! | BK31: =AVERAGE(BK6:BK29) -> #DIV/0! | BN31: =AVERAGE(BN6:BN29) -> #DIV/0! | BO31: =MAX(BN6:BN29) -> 0 | BP31: =MIN(BN6:BN29) -> 0 | BQ31: =AVERAGE(BO6:BO29) -> #DIV/0! | BR31: =MAX(BO6:BO29) -> 0 | BS31: =MIN(BO6:BO29) -> 0
A32: UPS: | B32: =AF32+AS32 -> #DIV/0! | C32: =AF33+AS33 -> 0 | L32: Max | M32: =MAX(M6:M29) -> 0 | AE32: Avg | AF32: =AVERAGE(AF6:AF29) -> #DIV/0! | AR32: Avg | AS32: =AVERAGE(AS6:AS29) -> #DIV/0! | BE32: Max | BF32: =MAX(BF6:BF29) -> 0 | BG32: =MAX(BG6:BG29) -> 0 | BH32: =BF31*BG31 -> #DIV/0! | BJ32: =MAX(BJ6:BJ29) -> 0 | BK32: =MAX(BK6:BK29) -> 0 | BL32: =BJ31*BK31 -> #DIV/0!
A33: Rectifier: | B33: =(BH32+BL32)/1000 -> #DIV/0! | C33: =(BH33+BL33)/1000 -> 0 | AE33: Max | AF33: =MAX(AF6:AF29) -> 0 | AR33: Max | AS33: =MAX(AS6:AS29) -> 0 | BH33: =BF32*BG32 -> 0 | BL33: =BJ32*BK32 -> 0
A39: Technician signature | R39: Engineer signature
A45: DAILY DIARY
A46: Date | B46: Time | C46: Observations &Activities done on the duty

Sheet 3
A1: Switch Power & Room temperature Log Sheet | BV1: ='2'!BV1:CC1+1 -> 46176
A2: Zesco Load Details | N2: DG Load Details | AF2: Ground Floor | BV2: First Floor | CA2: Second Floor | CB2: Load On | CC2: Shift Tech
AF3: Inverter Readings | BF3: Rectifier Readings | BN3: Temperature in Centigrade | BZ3: Condition
A4: Time | B4: Load On Grid in AMPs | E4: Grid Voltage Line to Line | H4: Grid frequency | I4: Grid Power Status ON/ OFF | J4: Grid Off Time | K4: Grid Restored Time | L4: Grid off Duration | M4: Site Load ( ZESCO Or Generator) in kw | N4: Load On DG in AMPs | Q4: DG Voltage Line to Line | T4: DG-1 Run Hrs | U4: DG 1 Battery Voltage | V4: Charged Status (Color) | W4: DG-2 Run Hrs | X4: DG 2 Battery Voltage | Y4: Charged Status (Color) | Z4: DG-3 Run Hrs | AA4: DG 3 Battery Voltage | AB4: Charged Status (Color) | AC4: DG-4 Run Hrs | AD4: DG 4 Battery Voltage | AE4: Charged Status (Color) | AF4: UPS1-POWER PLANT ROOM-1 | AS4: UPS2-POWER PLANT ROOM-2 | BF4: Rectifier 1 - Voltage / Amps | BI4: Used Percentage | BJ4: Rectifier 2 - Voltage / Amps | BM4: Used Percentage | BN4: Room-1 Server & IT | BP4: Media Room | BR4: Power Room-1 | BT4: Power Room-2 | BV4: Room-1 | BX4: Room-2 | BZ4: Work Station | CA4: FM 200 Panel / WDS/Vesda Status
B5: R | C5: Y | D5: B | E5: R | F5: Y | G5: B | H5: HZ | N5: R | O5: Y | P5: B | Q5: R | R5: Y | S5: B | AF5: Output Load KW | AG5: Used Capacity | AH5: Battery Charge % | AI5: Battery Voltage (V) | AJ5: Load Current-A ( A) | AK5: Load Current-B ( A) | AL5: Load Current-C ( A) | AM5: Load Phase -A % | AN5: Load Phase -B % | AO5: Load Phase -C % | AP5: Output Voltage-A ( V) | AQ5: Output Voltage-B ( V) | AR5: Output Voltage-C ( V) | AS5: Output Load KW | AT5: Used Capacity | AU5: Battery Charge % | AV5: Battery Voltage (V) | AW5: Load Current-A ( A) | AX5: Load Current-B ( A) | AY5: Load Current-C ( A) | AZ5: Load Phase -A % | BA5: Load Phase -B % | BB5: Load Phase -C % | BC5: Output Voltage-A ( V) | BD5: Output Voltage-B ( V) | BE5: Output Voltage-C ( V) | BF5: DC Volatge | BG5: Current | BH5: Battery charge status | BJ5: DC Volatge | BK5: Current | BL5: Battery charge status | BN5: Temp | BO5: Hum | BP5: Temp | BQ5: Hum | BR5: Temp | BS5: Hum | BT5: Temp | BU5: Hum | BV5: Temp | BW5: Hum | BX5: Temp | BY5: Hum
A6: 0
A7: 0.041666667
A8: 0.083333333
A9: 0.125
A10: 0.16666667
A11: 0.20833333
A12: 0.25
A13: 0.29166667
A14: 0.33333333
A15: 0.375
A16: 0.41666667
A17: 0.45833333
... A29: 0.95833333
Y30: Green
B31: Average | C31: Maximum | L31: Average | M31: =AVERAGE(M6:M29) -> #DIV/0! | BE31: Average | BF31: =AVERAGE(BF6:BF29) -> #DIV/0! | BG31: =AVERAGE(BG6:BG29) -> #DIV/0! | BJ31: =AVERAGE(BJ6:BJ29) -> #DIV/0! | BK31: =AVERAGE(BK6:BK29) -> #DIV/0! | BN31: =AVERAGE(BN6:BN29) -> #DIV/0! | BO31: =MAX(BN6:BN29) -> 0 | BP31: =MIN(BN6:BN29) -> 0 | BQ31: =AVERAGE(BO6:BO29) -> #DIV/0! | BR31: =MAX(BO6:BO29) -> 0 | BS31: =MIN(BO6:BO29) -> 0
A32: UPS: | B32: =AF32+AS32 -> #DIV/0! | C32: =AF33+AS33 -> 0 | L32: Max | M32: =MAX(M6:M29) -> 0 | AE32: Avg | AF32: =AVERAGE(AF6:AF29) -> #DIV/0! | AR32: Avg | AS32: =AVERAGE(AS6:AS29) -> #DIV/0! | BE32: Max | BF32: =MAX(BF6:BF29) -> 0 | BG32: =MAX(BG6:BG29) -> 0 | BH32: =BF31*BG31 -> #DIV/0! | BJ32: =MAX(BJ6:BJ29) -> 0 | BK32: =MAX(BK6:BK29) -> 0 | BL32: =BJ31*BK31 -> #DIV/0!
A33: Rectifier: | B33: =(BH32+BL32)/1000 -> #DIV/0! | C33: =(BH33+BL33)/1000 -> 0 | AE33: Max | AF33: =MAX(AF6:AF29) -> 0 | AR33: Max | AS33: =MAX(AS6:AS29) -> 0 | BH33: =BF32*BG32 -> 0 | BL33: =BJ32*BK32 -> 0
A39: Technician signature | R39: Engineer signature
Q44: 405 | R44: 405 | S44: 405
A45: DAILY DIARY | Q45: 410 | R45: 410 | S45: 410
A46: Date | B46: Time | C46: Observations &Activities done on the duty | Q46: 407 | R46: 407 | S46: 407
Q47: 407 | R47: 407 | S47: 407
Q48: 409 | R48: 409 | S48: 410
Q49: 403 | R49: 403 | S49: 403
Q50: 405 | R50: 405 | S50: 405
Q51: 413 | R51: 413 | S51: 413
Q52: 407 | R52: 407 | S52: 407

Sheet 4
A1: Switch Power & Room temperature Log Sheet | BV1: ='3'!BV1:CC1+1 -> 46177
A2: Zesco Load Details | N2: DG Load Details | AF2: Ground Floor | BV2: First Floor | CA2: Second Floor | CB2: Load On | CC2: Shift Tech
AF3: Inverter Readings | BF3: Rectifier Readings | BN3: Temperature in Centigrade | BZ3: Condition
A4: Time | B4: Load On Grid in AMPs | E4: Grid Voltage Line to Line | H4: Grid frequency | I4: Grid Power Status ON/ OFF | J4: Grid Off Time | K4: Grid Restored Time | L4: Grid off Duration | M4: Site Load ( ZESCO Or Generator) in kw | N4: Load On DG in AMPs | Q4: DG Voltage Line to Line | T4: DG-1 Run Hrs | U4: DG 1 Battery Voltage | V4: Charged Status (Color) | W4: DG-2 Run Hrs | X4: DG 2 Battery Voltage | Y4: Charged Status (Color) | Z4: DG-3 Run Hrs | AA4: DG 3 Battery Voltage | AB4: Charged Status (Color) | AC4: DG-4 Run Hrs | AD4: DG 4 Battery Voltage | AE4: Charged Status (Color) | AF4: UPS1-POWER PLANT ROOM-1 | AS4: UPS2-POWER PLANT ROOM-2 | BF4: Rectifier 1 - Voltage / Amps | BI4: Used Percentage | BJ4: Rectifier 2 - Voltage / Amps | BM4: Used Percentage | BN4: Room-1 Server & IT | BP4: Media Room | BR4: Power Room-1 | BT4: Power Room-2 | BV4: Room-1 | BX4: Room-2 | BZ4: Work Station | CA4: FM 200 Panel / WDS/Vesda Status
B5: R | C5: Y | D5: B | E5: R | F5: Y | G5: B | H5: HZ | N5: R | O5: Y | P5: B | Q5: R | R5: Y | S5: B | AF5: Output Load KW | AG5: Used Capacity | AH5: Battery Charge % | AI5: Battery Voltage (V) | AJ5: Load Current-A ( A) | AK5: Load Current-B ( A) | AL5: Load Current-C ( A) | AM5: Load Phase -A % | AN5: Load Phase -B % | AO5: Load Phase -C % | AP5: Output Voltage-A ( V) | AQ5: Output Voltage-B ( V) | AR5: Output Voltage-C ( V) | AS5: Output Load KW | AT5: Used Capacity | AU5: Battery Charge % | AV5: Battery Voltage (V) | AW5: Load Current-A ( A) | AX5: Load Current-B ( A) | AY5: Load Current-C ( A) | AZ5: Load Phase -A % | BA5: Load Phase -B % | BB5: Load Phase -C % | BC5: Output Voltage-A ( V) | BD5: Output Voltage-B ( V) | BE5: Output Voltage-C ( V) | BF5: DC Volatge | BG5: Current | BH5: Battery charge status | BJ5: DC Volatge | BK5: Current | BL5: Battery charge status | BN5: Temp | BO5: Hum | BP5: Temp | BQ5: Hum | BR5: Temp | BS5: Hum | BT5: Temp | BU5: Hum | BV5: Temp | BW5: Hum | BX5: Temp | BY5: Hum
A6: 0
A7: 0.041666667
A8: 0.083333333
A9: 0.125
A10: 0.16666667
A11: 0.20833333
A12: 0.25
A13: 0.29166667
A14: 0.33333333
A15: 0.375
A16: 0.41666667
A17: 0.45833333
... A29: 0.95833333
Y30: Green
B31: Average | C31: Maximum | L31: Average | M31: =AVERAGE(M6:M29) -> #DIV/0! | BE31: Average | BF31: =AVERAGE(BF6:BF29) -> #DIV/0! | BG31: =AVERAGE(BG6:BG29) -> #DIV/0! | BJ31: =AVERAGE(BJ6:BJ29) -> #DIV/0! | BK31: =AVERAGE(BK6:BK29) -> #DIV/0! | BN31: =AVERAGE(BN6:BN29) -> #DIV/0! | BO31: =MAX(BN6:BN29) -> 0 | BP31: =MIN(BN6:BN29) -> 0 | BQ31: =AVERAGE(BO6:BO29) -> #DIV/0! | BR31: =MAX(BO6:BO29) -> 0 | BS31: =MIN(BO6:BO29) -> 0
A32: UPS: | B32: =AF32+AS32 -> #DIV/0! | C32: =AF33+AS33 -> 0 | L32: Max | M32: =MAX(M6:M29) -> 0 | AE32: Avg | AF32: =AVERAGE(AF6:AF29) -> #DIV/0! | AR32: Avg | AS32: =AVERAGE(AS6:AS29) -> #DIV/0! | BE32: Max | BF32: =MAX(BF6:BF29) -> 0 | BG32: =MAX(BG6:BG29) -> 0 | BH32: =BF31*BG31 -> #DIV/0! | BJ32: =MAX(BJ6:BJ29) -> 0 | BK32: =MAX(BK6:BK29) -> 0 | BL32: =BJ31*BK31 -> #DIV/0!
A33: Rectifier: | B33: =(BH32+BL32)/1000 -> #DIV/0! | C33: =(BH33+BL33)/1000 -> 0 | AE33: Max | AF33: =MAX(AF6:AF29) -> 0 | AR33: Max | AS33: =MAX(AS6:AS29) -> 0 | BH33: =BF32*BG32 -> 0 | BL33: =BJ32*BK32 -> 0
A39: Technician signature | R39: Engineer signature
A45: DAILY DIARY
A46: Date | B46: Time | C46: Observations &Activities done on the duty

Sheet 5
A1: Switch Power & Room temperature Log Sheet | BV1: ='4'!BV1:CC1+1 -> 46178
A2: Zesco Load Details | N2: DG Load Details | AF2: Ground Floor | BV2: First Floor | CA2: Second Floor | CB2: Load On | CC2: Shift Tech
AF3: Inverter Readings | BF3: Rectifier Readings | BN3: Temperature in Centigrade | BZ3: Condition
A4: Time | B4: Load On Grid in AMPs | E4: Grid Voltage Line to Line | H4: Grid frequency | I4: Grid Power Status ON/ OFF | J4: Grid Off Time | K4: Grid Restored Time | L4: Grid off Duration | M4: Site Load ( ZESCO Or Generator) in kw | N4: Load On DG in AMPs | Q4: DG Voltage Line to Line | T4: DG-1 Run Hrs | U4: DG 1 Battery Voltage | V4: Charged Status (Color) | W4: DG-2 Run Hrs | X4: DG 2 Battery Voltage | Y4: Charged Status (Color) | Z4: DG-3 Run Hrs | AA4: DG 3 Battery Voltage | AB4: Charged Status (Color) | AC4: DG-4 Run Hrs | AD4: DG 4 Battery Voltage | AE4: Charged Status (Color) | AF4: UPS1-POWER PLANT ROOM-1 | AS4: UPS2-POWER PLANT ROOM-2 | BF4: Rectifier 1 - Voltage / Amps | BI4: Used Percentage | BJ4: Rectifier 2 - Voltage / Amps | BM4: Used Percentage | BN4: Room-1 Server & IT | BP4: Media Room | BR4: Power Room-1 | BT4: Power Room-2 | BV4: Room-1 | BX4: Room-2 | BZ4: Work Station | CA4: FM 200 Panel / WDS/Vesda Status
B5: R | C5: Y | D5: B | E5: R | F5: Y | G5: B | H5: HZ | N5: R | O5: Y | P5: B | Q5: R | R5: Y | S5: B | AF5: Output Load KW | AG5: Used Capacity | AH5: Battery Charge % | AI5: Battery Voltage (V) | AJ5: Load Current-A ( A) | AK5: Load Current-B ( A) | AL5: Load Current-C ( A) | AM5: Load Phase -A % | AN5: Load Phase -B % | AO5: Load Phase -C % | AP5: Output Voltage-A ( V) | AQ5: Output Voltage-B ( V) | AR5: Output Voltage-C ( V) | AS5: Output Load KW | AT5: Used Capacity | AU5: Battery Charge % | AV5: Battery Voltage (V) | AW5: Load Current-A ( A) | AX5: Load Current-B ( A) | AY5: Load Current-C ( A) | AZ5: Load Phase -A % | BA5: Load Phase -B % | BB5: Load Phase -C % | BC5: Output Voltage-A ( V) | BD5: Output Voltage-B ( V) | BE5: Output Voltage-C ( V) | BF5: DC Volatge | BG5: Current | BH5: Battery charge status | BJ5: DC Volatge | BK5: Current | BL5: Battery charge status | BN5: Temp | BO5: Hum | BP5: Temp | BQ5: Hum | BR5: Temp | BS5: Hum | BT5: Temp | BU5: Hum | BV5: Temp | BW5: Hum | BX5: Temp | BY5: Hum
A6: 0
A7: 0.041666667
A8: 0.083333333
A9: 0.125
A10: 0.16666667
A11: 0.20833333
A12: 0.25
A13: 0.29166667
A14: 0.33333333
A15: 0.375
A16: 0.41666667
A17: 0.45833333
... A29: 0.95833333
B31: Average | C31: Maximum | L31: Average | M31: =AVERAGE(M6:M29) -> #DIV/0! | BE31: Average | BF31: =AVERAGE(BF6:BF29) -> #DIV/0! | BG31: =AVERAGE(BG6:BG29) -> #DIV/0! | BJ31: =AVERAGE(BJ6:BJ29) -> #DIV/0! | BK31: =AVERAGE(BK6:BK29) -> #DIV/0! | BN31: =AVERAGE(BN6:BN29) -> #DIV/0! | BO31: =MAX(BN6:BN29) -> 0 | BP31: =MIN(BN6:BN29) -> 0 | BQ31: =AVERAGE(BO6:BO29) -> #DIV/0! | BR31: =MAX(BO6:BO29) -> 0 | BS31: =MIN(BO6:BO29) -> 0
A32: UPS: | B32: =AF32+AS32 -> #DIV/0! | C32: =AF33+AS33 -> 0 | L32: Max | M32: =MAX(M6:M29) -> 0 | AE32: Avg | AF32: =AVERAGE(AF6:AF29) -> #DIV/0! | AR32: Avg | AS32: =AVERAGE(AS6:AS29) -> #DIV/0! | BE32: Max | BF32: =MAX(BF6:BF29) -> 0 | BG32: =MAX(BG6:BG29) -> 0 | BH32: =BF31*BG31 -> #DIV/0! | BJ32: =MAX(BJ6:BJ29) -> 0 | BK32: =MAX(BK6:BK29) -> 0 | BL32: =BJ31*BK31 -> #DIV/0!
A33: Rectifier: | B33: =(BH32+BL32)/1000 -> #DIV/0! | C33: =(BH33+BL33)/1000 -> 0 | AE33: Max | AF33: =MAX(AF6:AF29) -> 0 | AR33: Max | AS33: =MAX(AS6:AS29) -> 0 | BH33: =BF32*BG32 -> 0 | BL33: =BJ32*BK32 -> 0
A39: Technician signature | R39: Engineer signature
A45: DAILY DIARY
A46: Date | B46: Time | C46: Observations &Activities done on the duty

Sheet 6
A1: Switch Power & Room temperature Log Sheet | BV1: ='5'!BV1:CC1+1 -> 46179
A2: Zesco Load Details | N2: DG Load Details | AF2: Ground Floor | BV2: First Floor | CA2: Second Floor | CB2: Load On | CC2: Shift Tech
AF3: Inverter Readings | BF3: Rectifier Readings | BN3: Temperature in Centigrade | BZ3: Condition
A4: Time | B4: Load On Grid in AMPs | E4: Grid Voltage Line to Line | H4: Grid frequency | I4: Grid Power Status ON/ OFF | J4: Grid Off Time | K4: Grid Restored Time | L4: Grid off Duration | M4: Site Load ( ZESCO Or Generator) in kw | N4: Load On DG in AMPs | Q4: DG Voltage Line to Line | T4: DG-1 Run Hrs | U4: DG 1 Battery Voltage | V4: Charged Status (Color) | W4: DG-2 Run Hrs | X4: DG 2 Battery Voltage | Y4: Charged Status (Color) | Z4: DG-3 Run Hrs | AA4: DG 3 Battery Voltage | AB4: Charged Status (Color) | AC4: DG-4 Run Hrs | AD4: DG 4 Battery Voltage | AE4: Charged Status (Color) | AF4: UPS1-POWER PLANT ROOM-1 | AS4: UPS2-POWER PLANT ROOM-2 | BF4: Rectifier 1 - Voltage / Amps | BI4: Used Percentage | BJ4: Rectifier 2 - Voltage / Amps | BM4: Used Percentage | BN4: Room-1 Server & IT | BP4: Media Room | BR4: Power Room-1 | BT4: Power Room-2 | BV4: Room-1 | BX4: Room-2 | BZ4: Work Station | CA4: FM 200 Panel / WDS/Vesda Status
B5: R | C5: Y | D5: B | E5: R | F5: Y | G5: B | H5: HZ | N5: R | O5: Y | P5: B | Q5: R | R5: Y | S5: B | AF5: Output Load KW | AG5: Used Capacity | AH5: Battery Charge % | AI5: Battery Voltage (V) | AJ5: Load Current-A ( A) | AK5: Load Current-B ( A) | AL5: Load Current-C ( A) | AM5: Load Phase -A % | AN5: Load Phase -B % | AO5: Load Phase -C % | AP5: Output Voltage-A ( V) | AQ5: Output Voltage-B ( V) | AR5: Output Voltage-C ( V) | AS5: Output Load KW | AT5: Used Capacity | AU5: Battery Charge % | AV5: Battery Voltage (V) | AW5: Load Current-A ( A) | AX5: Load Current-B ( A) | AY5: Load Current-C ( A) | AZ5: Load Phase -A % | BA5: Load Phase -B % | BB5: Load Phase -C % | BC5: Output Voltage-A ( V) | BD5: Output Voltage-B ( V) | BE5: Output Voltage-C ( V) | BF5: DC Volatge | BG5: Current | BH5: Battery charge status | BJ5: DC Volatge | BK5: Current | BL5: Battery charge status | BN5: Temp | BO5: Hum | BP5: Temp | BQ5: Hum | BR5: Temp | BS5: Hum | BT5: Temp | BU5: Hum | BV5: Temp | BW5: Hum | BX5: Temp | BY5: Hum
A6: 0
A7: 0.041666667
A8: 0.083333333
A9: 0.125
A10: 0.16666667
A11: 0.20833333
A12: 0.25
A13: 0.29166667
A14: 0.33333333
A15: 0.375
A16: 0.41666667
A17: 0.45833333
... A29: 0.95833333
B31: Average | C31: Maximum | L31: Average | M31: =AVERAGE(M6:M29) -> #DIV/0! | BE31: Average | BF31: =AVERAGE(BF6:BF29) -> #DIV/0! | BG31: =AVERAGE(BG6:BG29) -> #DIV/0! | BJ31: =AVERAGE(BJ6:BJ29) -> #DIV/0! | BK31: =AVERAGE(BK6:BK29) -> #DIV/0! | BN31: =AVERAGE(BN6:BN29) -> #DIV/0! | BO31: =MAX(BN6:BN29) -> 0 | BP31: =MIN(BN6:BN29) -> 0 | BQ31: =AVERAGE(BO6:BO29) -> #DIV/0! | BR31: =MAX(BO6:BO29) -> 0 | BS31: =MIN(BO6:BO29) -> 0
A32: UPS: | B32: =AF32+AS32 -> #DIV/0! | C32: =AF33+AS33 -> 0 | L32: Max | M32: =MAX(M6:M29) -> 0 | AE32: Avg | AF32: =AVERAGE(AF6:AF29) -> #DIV/0! | AR32: Avg | AS32: =AVERAGE(AS6:AS29) -> #DIV/0! | BE32: Max | BF32: =MAX(BF6:BF29) -> 0 | BG32: =MAX(BG6:BG29) -> 0 | BH32: =BF31*BG31 -> #DIV/0! | BJ32: =MAX(BJ6:BJ29) -> 0 | BK32: =MAX(BK6:BK29) -> 0 | BL32: =BJ31*BK31 -> #DIV/0!
A33: Rectifier: | B33: =(BH32+BL32)/1000 -> #DIV/0! | C33: =(BH33+BL33)/1000 -> 0 | AE33: Max | AF33: =MAX(AF6:AF29) -> 0 | AR33: Max | AS33: =MAX(AS6:AS29) -> 0 | BH33: =BF32*BG32 -> 0 | BL33: =BJ32*BK32 -> 0
A39: Technician signature | R39: Engineer signature
A45: DAILY DIARY
A46: Date | B46: Time | C46: Observations &Activities done on the duty

Sheet 7
A1: Switch Power & Room temperature Log Sheet | BV1: ='6'!BV1:CC1+1 -> 46180
A2: Zesco Load Details | N2: DG Load Details | AF2: Ground Floor | BV2: First Floor | CA2: Second Floor | CB2: Load On | CC2: Shift Tech
AF3: Inverter Readings | BF3: Rectifier Readings | BN3: Temperature in Centigrade | BZ3: Condition
A4: Time | B4: Load On Grid in AMPs | E4: Grid Voltage Line to Line | H4: Grid frequency | I4: Grid Power Status ON/ OFF | J4: Grid Off Time | K4: Grid Restored Time | L4: Grid off Duration | M4: Site Load ( ZESCO Or Generator) in kw | N4: Load On DG in AMPs | Q4: DG Voltage Line to Line | T4: DG-1 Run Hrs | U4: DG 1 Battery Voltage | V4: Charged Status (Color) | W4: DG-2 Run Hrs | X4: DG 2 Battery Voltage | Y4: Charged Status (Color) | Z4: DG-3 Run Hrs | AA4: DG 3 Battery Voltage | AB4: Charged Status (Color) | AC4: DG-4 Run Hrs | AD4: DG 4 Battery Voltage | AE4: Charged Status (Color) | AF4: UPS1-POWER PLANT ROOM-1 | AS4: UPS2-POWER PLANT ROOM-2 | BF4: Rectifier 1 - Voltage / Amps | BI4: Used Percentage | BJ4: Rectifier 2 - Voltage / Amps | BM4: Used Percentage | BN4: Room-1 Server & IT | BP4: Media Room | BR4: Power Room-1 | BT4: Power Room-2 | BV4: Room-1 | BX4: Room-2 | BZ4: Work Station | CA4: FM 200 Panel / WDS/Vesda Status
B5: R | C5: Y | D5: B | E5: R | F5: Y | G5: B | H5: HZ | N5: R | O5: Y | P5: B | Q5: R | R5: Y | S5: B | AF5: Output Load KW | AG5: Used Capacity | AH5: Battery Charge % | AI5: Battery Voltage (V) | AJ5: Load Current-A ( A) | AK5: Load Current-B ( A) | AL5: Load Current-C ( A) | AM5: Load Phase -A % | AN5: Load Phase -B % | AO5: Load Phase -C % | AP5: Output Voltage-A ( V) | AQ5: Output Voltage-B ( V) | AR5: Output Voltage-C ( V) | AS5: Output Load KW | AT5: Used Capacity | AU5: Battery Charge % | AV5: Battery Voltage (V) | AW5: Load Current-A ( A) | AX5: Load Current-B ( A) | AY5: Load Current-C ( A) | AZ5: Load Phase -A % | BA5: Load Phase -B % | BB5: Load Phase -C % | BC5: Output Voltage-A ( V) | BD5: Output Voltage-B ( V) | BE5: Output Voltage-C ( V) | BF5: DC Volatge | BG5: Current | BH5: Battery charge status | BJ5: DC Volatge | BK5: Current | BL5: Battery charge status | BN5: Temp | BO5: Hum | BP5: Temp | BQ5: Hum | BR5: Temp | BS5: Hum | BT5: Temp | BU5: Hum | BV5: Temp | BW5: Hum | BX5: Temp | BY5: Hum
A6: 0
A7: 0.041666667
A8: 0.083333333
A9: 0.125
A10: 0.16666667
A11: 0.20833333
A12: 0.25
A13: 0.29166667
A14: 0.33333333
A15: 0.375
A16: 0.41666667
A17: 0.45833333
... A29: 0.95833333
B31: Average | C31: Maximum | L31: Average | M31: =AVERAGE(M6:M29) -> #DIV/0! | BE31: Average | BF31: =AVERAGE(BF6:BF29) -> #DIV/0! | BG31: =AVERAGE(BG6:BG29) -> #DIV/0! | BJ31: =AVERAGE(BJ6:BJ29) -> #DIV/0! | BK31: =AVERAGE(BK6:BK29) -> #DIV/0! | BN31: =AVERAGE(BN6:BN29) -> #DIV/0! | BO31: =MAX(BN6:BN29) -> 0 | BP31: =MIN(BN6:BN29) -> 0 | BQ31: =AVERAGE(BO6:BO29) -> #DIV/0! | BR31: =MAX(BO6:BO29) -> 0 | BS31: =MIN(BO6:BO29) -> 0
